[2025-04-18T19:30:19.246+0000] {taskinstance.py:1956} INFO - Dependencies all met for dep_context=non-requeueable deps ti=<TaskInstance: nasa_apod_postgres.create_table manual__2025-04-18T19:30:18.935532+00:00 [queued]>
[2025-04-18T19:30:19.250+0000] {taskinstance.py:1956} INFO - Dependencies all met for dep_context=requeueable deps ti=<TaskInstance: nasa_apod_postgres.create_table manual__2025-04-18T19:30:18.935532+00:00 [queued]>
[2025-04-18T19:30:19.251+0000] {taskinstance.py:2170} INFO - Starting attempt 1 of 1
[2025-04-18T19:30:19.258+0000] {taskinstance.py:2191} INFO - Executing <Task(_PythonDecoratedOperator): create_table> on 2025-04-18 19:30:18.935532+00:00
[2025-04-18T19:30:19.261+0000] {standard_task_runner.py:60} INFO - Started process 245 to run task
[2025-04-18T19:30:19.264+0000] {standard_task_runner.py:87} INFO - Running: ['airflow', 'tasks', 'run', 'nasa_apod_***', 'create_table', 'manual__2025-04-18T19:30:18.935532+00:00', '--job-id', '2', '--raw', '--subdir', 'DAGS_FOLDER/etl.py', '--cfg-path', '/tmp/tmpy0zd16xu']
[2025-04-18T19:30:19.265+0000] {standard_task_runner.py:88} INFO - Job 2: Subtask create_table
[2025-04-18T19:30:19.276+0000] {logging_mixin.py:188} WARNING - /home/airflow/.local/lib/python3.8/site-packages/airflow/settings.py:194 DeprecationWarning: The sql_alchemy_conn option in [core] has been moved to the sql_alchemy_conn option in [database] - the old setting has been used, but please update your config.
[2025-04-18T19:30:19.299+0000] {task_command.py:423} INFO - Running <TaskInstance: nasa_apod_postgres.create_table manual__2025-04-18T19:30:18.935532+00:00 [running]> on host 51d45ce4c155
[2025-04-18T19:30:19.347+0000] {taskinstance.py:2480} INFO - Exporting env vars: AIRFLOW_CTX_DAG_OWNER='airflow' AIRFLOW_CTX_DAG_ID='nasa_apod_***' AIRFLOW_CTX_TASK_ID='create_table' AIRFLOW_CTX_EXECUTION_DATE='2025-04-18T19:30:18.935532+00:00' AIRFLOW_CTX_TRY_NUMBER='1' AIRFLOW_CTX_DAG_RUN_ID='manual__2025-04-18T19:30:18.935532+00:00'
[2025-04-18T19:30:19.357+0000] {taskinstance.py:2698} ERROR - Task failed with exception
Traceback (most recent call last):
  File "/home/airflow/.local/lib/python3.8/site-packages/airflow/models/taskinstance.py", line 433, in _execute_task
    result = execute_callable(context=context, **execute_callable_kwargs)
  File "/home/airflow/.local/lib/python3.8/site-packages/airflow/decorators/base.py", line 241, in execute
    return_value = super().execute(context)
  File "/home/airflow/.local/lib/python3.8/site-packages/airflow/operators/python.py", line 199, in execute
    return_value = self.execute_callable()
  File "/home/airflow/.local/lib/python3.8/site-packages/airflow/operators/python.py", line 216, in execute_callable
    return self.python_callable(*self.op_args, **self.op_kwargs)
  File "/opt/airflow/dags/etl.py", line 39, in create_table
    postgres_hook.run(create_table_query)
  File "/home/airflow/.local/lib/python3.8/site-packages/airflow/providers/common/sql/hooks/sql.py", line 391, in run
    with closing(self.get_conn()) as conn:
  File "/home/airflow/.local/lib/python3.8/site-packages/airflow/providers/postgres/hooks/postgres.py", line 128, in get_conn
    conn = deepcopy(self.connection or self.get_connection(conn_id))
  File "/home/airflow/.local/lib/python3.8/site-packages/airflow/hooks/base.py", line 82, in get_connection
    conn = Connection.get_connection_from_secrets(conn_id)
  File "/home/airflow/.local/lib/python3.8/site-packages/airflow/models/connection.py", line 479, in get_connection_from_secrets
    raise AirflowNotFoundException(f"The conn_id `{conn_id}` isn't defined")
airflow.exceptions.AirflowNotFoundException: The conn_id `my_***_connection` isn't defined
[2025-04-18T19:30:19.361+0000] {taskinstance.py:1138} INFO - Marking task as FAILED. dag_id=nasa_apod_***, task_id=create_table, execution_date=20250418T193018, start_date=20250418T193019, end_date=20250418T193019
[2025-04-18T19:30:19.368+0000] {standard_task_runner.py:107} ERROR - Failed to execute job 2 for task create_table (The conn_id `my_***_connection` isn't defined; 245)
[2025-04-18T19:30:19.396+0000] {local_task_job_runner.py:234} INFO - Task exited with return code 1
[2025-04-18T19:30:19.409+0000] {taskinstance.py:3280} INFO - 0 downstream tasks scheduled from follow-on schedule check
