[2025-04-18T19:30:19.245+0000] {taskinstance.py:1956} INFO - Dependencies all met for dep_context=non-requeueable deps ti=<TaskInstance: nasa_apod_postgres.create_table scheduled__2025-04-17T00:00:00+00:00 [queued]>
[2025-04-18T19:30:19.250+0000] {taskinstance.py:1956} INFO - Dependencies all met for dep_context=requeueable deps ti=<TaskInstance: nasa_apod_postgres.create_table scheduled__2025-04-17T00:00:00+00:00 [queued]>
[2025-04-18T19:30:19.251+0000] {taskinstance.py:2170} INFO - Starting attempt 1 of 1
[2025-04-18T19:30:19.258+0000] {taskinstance.py:2191} INFO - Executing <Task(_PythonDecoratedOperator): create_table> on 2025-04-17 00:00:00+00:00
[2025-04-18T19:30:19.261+0000] {standard_task_runner.py:60} INFO - Started process 246 to run task
[2025-04-18T19:30:19.265+0000] {standard_task_runner.py:87} INFO - Running: ['airflow', 'tasks', 'run', 'nasa_apod_***', 'create_table', 'scheduled__2025-04-17T00:00:00+00:00', '--job-id', '3', '--raw', '--subdir', 'DAGS_FOLDER/etl.py', '--cfg-path', '/tmp/tmpj4nc_lh1']
[2025-04-18T19:30:19.266+0000] {standard_task_runner.py:88} INFO - Job 3: Subtask create_table
[2025-04-18T19:30:19.275+0000] {logging_mixin.py:188} WARNING - /home/airflow/.local/lib/python3.8/site-packages/airflow/settings.py:194 DeprecationWarning: The sql_alchemy_conn option in [core] has been moved to the sql_alchemy_conn option in [database] - the old setting has been used, but please update your config.
[2025-04-18T19:30:19.300+0000] {task_command.py:423} INFO - Running <TaskInstance: nasa_apod_postgres.create_table scheduled__2025-04-17T00:00:00+00:00 [running]> on host 51d45ce4c155
[2025-04-18T19:30:19.348+0000] {taskinstance.py:2480} INFO - Exporting env vars: AIRFLOW_CTX_DAG_OWNER='airflow' AIRFLOW_CTX_DAG_ID='nasa_apod_***' AIRFLOW_CTX_TASK_ID='create_table' AIRFLOW_CTX_EXECUTION_DATE='2025-04-17T00:00:00+00:00' AIRFLOW_CTX_TRY_NUMBER='1' AIRFLOW_CTX_DAG_RUN_ID='scheduled__2025-04-17T00:00:00+00:00'
[2025-04-18T19:30:19.356+0000] {taskinstance.py:2698} ERROR - Task failed with exception
Traceback (most recent call last):
  File "/home/airflow/.local/lib/python3.8/site-packages/airflow/models/taskinstance.py", line 433, in _execute_task
    result = execute_callable(context=context, **execute_callable_kwargs)
  File "/home/airflow/.local/lib/python3.8/site-packages/airflow/decorators/base.py", line 241, in execute
    return_value = super().execute(context)
  File "/home/airflow/.local/lib/python3.8/site-packages/airflow/operators/python.py", line 199, in execute
    return_value = self.execute_callable()
  File "/home/airflow/.local/lib/python3.8/site-packages/airflow/operators/python.py", line 216, in execute_callable
    return self.python_callable(*self.op_args, **self.op_kwargs)
  File "/opt/airflow/dags/etl.py", line 39, in create_table
    postgres_hook.run(create_table_query)
  File "/home/airflow/.local/lib/python3.8/site-packages/airflow/providers/common/sql/hooks/sql.py", line 391, in run
    with closing(self.get_conn()) as conn:
  File "/home/airflow/.local/lib/python3.8/site-packages/airflow/providers/postgres/hooks/postgres.py", line 128, in get_conn
    conn = deepcopy(self.connection or self.get_connection(conn_id))
  File "/home/airflow/.local/lib/python3.8/site-packages/airflow/hooks/base.py", line 82, in get_connection
    conn = Connection.get_connection_from_secrets(conn_id)
  File "/home/airflow/.local/lib/python3.8/site-packages/airflow/models/connection.py", line 479, in get_connection_from_secrets
    raise AirflowNotFoundException(f"The conn_id `{conn_id}` isn't defined")
airflow.exceptions.AirflowNotFoundException: The conn_id `my_***_connection` isn't defined
[2025-04-18T19:30:19.361+0000] {taskinstance.py:1138} INFO - Marking task as FAILED. dag_id=nasa_apod_***, task_id=create_table, execution_date=20250417T000000, start_date=20250418T193019, end_date=20250418T193019
[2025-04-18T19:30:19.368+0000] {standard_task_runner.py:107} ERROR - Failed to execute job 3 for task create_table (The conn_id `my_***_connection` isn't defined; 246)
[2025-04-18T19:30:19.396+0000] {local_task_job_runner.py:234} INFO - Task exited with return code 1
[2025-04-18T19:30:19.409+0000] {taskinstance.py:3280} INFO - 0 downstream tasks scheduled from follow-on schedule check
[2025-04-18T19:40:00.159+0000] {taskinstance.py:1956} INFO - Dependencies all met for dep_context=non-requeueable deps ti=<TaskInstance: nasa_apod_postgres.create_table scheduled__2025-04-17T00:00:00+00:00 [queued]>
[2025-04-18T19:40:00.164+0000] {taskinstance.py:1956} INFO - Dependencies all met for dep_context=requeueable deps ti=<TaskInstance: nasa_apod_postgres.create_table scheduled__2025-04-17T00:00:00+00:00 [queued]>
[2025-04-18T19:40:00.165+0000] {taskinstance.py:2170} INFO - Starting attempt 1 of 1
[2025-04-18T19:40:00.172+0000] {taskinstance.py:2191} INFO - Executing <Task(_PythonDecoratedOperator): create_table> on 2025-04-17 00:00:00+00:00
[2025-04-18T19:40:00.176+0000] {standard_task_runner.py:60} INFO - Started process 205 to run task
[2025-04-18T19:40:00.181+0000] {standard_task_runner.py:87} INFO - Running: ['airflow', 'tasks', 'run', 'nasa_apod_***', 'create_table', 'scheduled__2025-04-17T00:00:00+00:00', '--job-id', '2', '--raw', '--subdir', 'DAGS_FOLDER/etl.py', '--cfg-path', '/tmp/tmpindaaurl']
[2025-04-18T19:40:00.183+0000] {standard_task_runner.py:88} INFO - Job 2: Subtask create_table
[2025-04-18T19:40:00.192+0000] {logging_mixin.py:188} WARNING - /home/airflow/.local/lib/python3.8/site-packages/airflow/settings.py:194 DeprecationWarning: The sql_alchemy_conn option in [core] has been moved to the sql_alchemy_conn option in [database] - the old setting has been used, but please update your config.
[2025-04-18T19:40:00.215+0000] {task_command.py:423} INFO - Running <TaskInstance: nasa_apod_postgres.create_table scheduled__2025-04-17T00:00:00+00:00 [running]> on host b13dae5b055f
[2025-04-18T19:40:00.254+0000] {taskinstance.py:2480} INFO - Exporting env vars: AIRFLOW_CTX_DAG_OWNER='airflow' AIRFLOW_CTX_DAG_ID='nasa_apod_***' AIRFLOW_CTX_TASK_ID='create_table' AIRFLOW_CTX_EXECUTION_DATE='2025-04-17T00:00:00+00:00' AIRFLOW_CTX_TRY_NUMBER='1' AIRFLOW_CTX_DAG_RUN_ID='scheduled__2025-04-17T00:00:00+00:00'
[2025-04-18T19:40:00.263+0000] {taskinstance.py:2698} ERROR - Task failed with exception
Traceback (most recent call last):
  File "/home/airflow/.local/lib/python3.8/site-packages/airflow/models/taskinstance.py", line 433, in _execute_task
    result = execute_callable(context=context, **execute_callable_kwargs)
  File "/home/airflow/.local/lib/python3.8/site-packages/airflow/decorators/base.py", line 241, in execute
    return_value = super().execute(context)
  File "/home/airflow/.local/lib/python3.8/site-packages/airflow/operators/python.py", line 199, in execute
    return_value = self.execute_callable()
  File "/home/airflow/.local/lib/python3.8/site-packages/airflow/operators/python.py", line 216, in execute_callable
    return self.python_callable(*self.op_args, **self.op_kwargs)
  File "/opt/airflow/dags/etl.py", line 39, in create_table
    postgres_hook.run(create_table_query)
  File "/home/airflow/.local/lib/python3.8/site-packages/airflow/providers/common/sql/hooks/sql.py", line 391, in run
    with closing(self.get_conn()) as conn:
  File "/home/airflow/.local/lib/python3.8/site-packages/airflow/providers/postgres/hooks/postgres.py", line 128, in get_conn
    conn = deepcopy(self.connection or self.get_connection(conn_id))
  File "/home/airflow/.local/lib/python3.8/site-packages/airflow/hooks/base.py", line 82, in get_connection
    conn = Connection.get_connection_from_secrets(conn_id)
  File "/home/airflow/.local/lib/python3.8/site-packages/airflow/models/connection.py", line 479, in get_connection_from_secrets
    raise AirflowNotFoundException(f"The conn_id `{conn_id}` isn't defined")
airflow.exceptions.AirflowNotFoundException: The conn_id `my_***_connection` isn't defined
[2025-04-18T19:40:00.267+0000] {taskinstance.py:1138} INFO - Marking task as FAILED. dag_id=nasa_apod_***, task_id=create_table, execution_date=20250417T000000, start_date=20250418T194000, end_date=20250418T194000
[2025-04-18T19:40:00.273+0000] {standard_task_runner.py:107} ERROR - Failed to execute job 2 for task create_table (The conn_id `my_***_connection` isn't defined; 205)
[2025-04-18T19:40:00.310+0000] {local_task_job_runner.py:234} INFO - Task exited with return code 1
[2025-04-18T19:40:00.325+0000] {taskinstance.py:3280} INFO - 0 downstream tasks scheduled from follow-on schedule check
[2025-04-18T19:56:47.364+0000] {taskinstance.py:1956} INFO - Dependencies all met for dep_context=non-requeueable deps ti=<TaskInstance: nasa_apod_postgres.create_table scheduled__2025-04-17T00:00:00+00:00 [queued]>
[2025-04-18T19:56:47.369+0000] {taskinstance.py:1956} INFO - Dependencies all met for dep_context=requeueable deps ti=<TaskInstance: nasa_apod_postgres.create_table scheduled__2025-04-17T00:00:00+00:00 [queued]>
[2025-04-18T19:56:47.370+0000] {taskinstance.py:2170} INFO - Starting attempt 1 of 1
[2025-04-18T19:56:47.378+0000] {taskinstance.py:2191} INFO - Executing <Task(_PythonDecoratedOperator): create_table> on 2025-04-17 00:00:00+00:00
[2025-04-18T19:56:47.381+0000] {standard_task_runner.py:60} INFO - Started process 275 to run task
[2025-04-18T19:56:47.383+0000] {standard_task_runner.py:87} INFO - Running: ['airflow', 'tasks', 'run', 'nasa_apod_***', 'create_table', 'scheduled__2025-04-17T00:00:00+00:00', '--job-id', '2', '--raw', '--subdir', 'DAGS_FOLDER/etl.py', '--cfg-path', '/tmp/tmph4mgqx0x']
[2025-04-18T19:56:47.384+0000] {standard_task_runner.py:88} INFO - Job 2: Subtask create_table
[2025-04-18T19:56:47.394+0000] {logging_mixin.py:188} WARNING - /home/airflow/.local/lib/python3.8/site-packages/airflow/settings.py:194 DeprecationWarning: The sql_alchemy_conn option in [core] has been moved to the sql_alchemy_conn option in [database] - the old setting has been used, but please update your config.
[2025-04-18T19:56:47.415+0000] {task_command.py:423} INFO - Running <TaskInstance: nasa_apod_postgres.create_table scheduled__2025-04-17T00:00:00+00:00 [running]> on host 4d4fb407ffc6
[2025-04-18T19:56:47.460+0000] {taskinstance.py:2480} INFO - Exporting env vars: AIRFLOW_CTX_DAG_OWNER='airflow' AIRFLOW_CTX_DAG_ID='nasa_apod_***' AIRFLOW_CTX_TASK_ID='create_table' AIRFLOW_CTX_EXECUTION_DATE='2025-04-17T00:00:00+00:00' AIRFLOW_CTX_TRY_NUMBER='1' AIRFLOW_CTX_DAG_RUN_ID='scheduled__2025-04-17T00:00:00+00:00'
[2025-04-18T19:56:47.469+0000] {taskinstance.py:2698} ERROR - Task failed with exception
Traceback (most recent call last):
  File "/home/airflow/.local/lib/python3.8/site-packages/airflow/models/taskinstance.py", line 433, in _execute_task
    result = execute_callable(context=context, **execute_callable_kwargs)
  File "/home/airflow/.local/lib/python3.8/site-packages/airflow/decorators/base.py", line 241, in execute
    return_value = super().execute(context)
  File "/home/airflow/.local/lib/python3.8/site-packages/airflow/operators/python.py", line 199, in execute
    return_value = self.execute_callable()
  File "/home/airflow/.local/lib/python3.8/site-packages/airflow/operators/python.py", line 216, in execute_callable
    return self.python_callable(*self.op_args, **self.op_kwargs)
  File "/opt/airflow/dags/etl.py", line 39, in create_table
    postgres_hook.run(create_table_query)
  File "/home/airflow/.local/lib/python3.8/site-packages/airflow/providers/common/sql/hooks/sql.py", line 391, in run
    with closing(self.get_conn()) as conn:
  File "/home/airflow/.local/lib/python3.8/site-packages/airflow/providers/postgres/hooks/postgres.py", line 128, in get_conn
    conn = deepcopy(self.connection or self.get_connection(conn_id))
  File "/home/airflow/.local/lib/python3.8/site-packages/airflow/hooks/base.py", line 82, in get_connection
    conn = Connection.get_connection_from_secrets(conn_id)
  File "/home/airflow/.local/lib/python3.8/site-packages/airflow/models/connection.py", line 479, in get_connection_from_secrets
    raise AirflowNotFoundException(f"The conn_id `{conn_id}` isn't defined")
airflow.exceptions.AirflowNotFoundException: The conn_id `my_***_connection` isn't defined
[2025-04-18T19:56:47.473+0000] {taskinstance.py:1138} INFO - Marking task as FAILED. dag_id=nasa_apod_***, task_id=create_table, execution_date=20250417T000000, start_date=20250418T195647, end_date=20250418T195647
[2025-04-18T19:56:47.479+0000] {standard_task_runner.py:107} ERROR - Failed to execute job 2 for task create_table (The conn_id `my_***_connection` isn't defined; 275)
[2025-04-18T19:56:47.515+0000] {local_task_job_runner.py:234} INFO - Task exited with return code 1
[2025-04-18T19:56:47.528+0000] {taskinstance.py:3280} INFO - 0 downstream tasks scheduled from follow-on schedule check
[2025-04-18T20:01:35.782+0000] {taskinstance.py:1956} INFO - Dependencies all met for dep_context=non-requeueable deps ti=<TaskInstance: nasa_apod_postgres.create_table scheduled__2025-04-17T00:00:00+00:00 [queued]>
[2025-04-18T20:01:35.786+0000] {taskinstance.py:1956} INFO - Dependencies all met for dep_context=requeueable deps ti=<TaskInstance: nasa_apod_postgres.create_table scheduled__2025-04-17T00:00:00+00:00 [queued]>
[2025-04-18T20:01:35.787+0000] {taskinstance.py:2170} INFO - Starting attempt 1 of 1
[2025-04-18T20:01:35.794+0000] {taskinstance.py:2191} INFO - Executing <Task(_PythonDecoratedOperator): create_table> on 2025-04-17 00:00:00+00:00
[2025-04-18T20:01:35.797+0000] {standard_task_runner.py:60} INFO - Started process 328 to run task
[2025-04-18T20:01:35.799+0000] {standard_task_runner.py:87} INFO - Running: ['airflow', 'tasks', 'run', 'nasa_apod_***', 'create_table', 'scheduled__2025-04-17T00:00:00+00:00', '--job-id', '4', '--raw', '--subdir', 'DAGS_FOLDER/etl.py', '--cfg-path', '/tmp/tmpqeckl4mz']
[2025-04-18T20:01:35.801+0000] {standard_task_runner.py:88} INFO - Job 4: Subtask create_table
[2025-04-18T20:01:35.810+0000] {logging_mixin.py:188} WARNING - /home/airflow/.local/lib/python3.8/site-packages/airflow/settings.py:194 DeprecationWarning: The sql_alchemy_conn option in [core] has been moved to the sql_alchemy_conn option in [database] - the old setting has been used, but please update your config.
[2025-04-18T20:01:35.832+0000] {task_command.py:423} INFO - Running <TaskInstance: nasa_apod_postgres.create_table scheduled__2025-04-17T00:00:00+00:00 [running]> on host 4d4fb407ffc6
[2025-04-18T20:01:35.873+0000] {taskinstance.py:2480} INFO - Exporting env vars: AIRFLOW_CTX_DAG_OWNER='airflow' AIRFLOW_CTX_DAG_ID='nasa_apod_***' AIRFLOW_CTX_TASK_ID='create_table' AIRFLOW_CTX_EXECUTION_DATE='2025-04-17T00:00:00+00:00' AIRFLOW_CTX_TRY_NUMBER='1' AIRFLOW_CTX_DAG_RUN_ID='scheduled__2025-04-17T00:00:00+00:00'
[2025-04-18T20:01:35.878+0000] {base.py:83} INFO - Using connection ID 'my_***_connection' for task execution.
[2025-04-18T20:01:35.880+0000] {sql.py:450} INFO - Running statement: 
        CREATE TABLE IF NOT EXISTS apod_data (
            id SERIAL PRIMARY KEY,
            title VARCHAR(255),
            explanation TEXT,
            url TEXT,
            date DATE,
            media_type VARCHAR(50)
        );


        , parameters: None
[2025-04-18T20:01:35.886+0000] {python.py:201} INFO - Done. Returned value was: None
[2025-04-18T20:01:35.890+0000] {taskinstance.py:1138} INFO - Marking task as SUCCESS. dag_id=nasa_apod_***, task_id=create_table, execution_date=20250417T000000, start_date=20250418T200135, end_date=20250418T200135
[2025-04-18T20:01:35.932+0000] {local_task_job_runner.py:234} INFO - Task exited with return code 0
[2025-04-18T20:01:35.947+0000] {taskinstance.py:3280} INFO - 1 downstream tasks scheduled from follow-on schedule check
